Workbook
Name FER_EC: Feriados!$A$6:$A$120
Name FER_CO: Feriados!$D$6:$D$120

Sheet Instrucciones
A1: Informe de Capacity – Instrucciones
A2: Plantilla por mes calendario, prorrateada por días hábiles y feriados por país
A4: Cómo usar
A5: 1. Parametros: define el mes inicial del informe (se muestran 6 meses), horas estándar por día, umbrales y si se incluyen asignaciones 'Probable'.
A6: 2. Consultores: un consultor por fila, con su país (EC o CO) y horas diarias de capacidad (8 = tiempo completo, 4 = medio tiempo).
A7: 3. Feriados: revisa las listas de Ecuador y Colombia. Agrega vacaciones o feriados locales si aplica.
A8: 4. Asignaciones: una fila por consultor-proyecto con fecha inicio, fecha fin y horas semanales dedicadas a ese proyecto.
A9: 5. Capacity y Horas se calculan solos. No escribas en las celdas grises.
A11: Lógica de cálculo
A12: • Cada asignación se reparte por días hábiles (lunes a viernes, sin feriados del país del consultor) dentro de cada mes calendario.
A13: • Horas asignadas del mes = días hábiles de la asignación en ese mes × (horas semanales ÷ 5).
A14: • Capacidad del mes = días hábiles del mes en el país del consultor × horas diarias del consultor.
... A25: Feriados precargados según calendarios oficiales publicados a oct-2026; verifica decretos nuevos (en Ecuador el Gobierno puede añadir o mover días).

Sheet Capacity
A1: Informe de Capacity – % de asignación por consultor
A2: Mes calendario completo · días hábiles por país · asignado ÷ capacidad
A3: ="Periodo: "&TEXT(Asignaciones!J3,"mmm-yyyy")&" a "&TEXT(Asignaciones!O3,"mmm-yyyy")&IF(Parametros!B6="Sí"," · Incluye probables"," · Solo confirmados")
A5: Indicador | C5: =Asignaciones!J3 | D5: =Asignaciones!K3 | E5: =Asignaciones!L3 | F5: =Asignaciones!M3 | G5: =Asignaciones!N3 | H5: =Asignaciones!O3 | I5: Periodo | K5: Leyenda
A6: Utilización del equipo | C6: =IF(Horas!C66=0,"",Horas!J66/Horas!C66) | D6: =IF(Horas!D66=0,"",Horas!K66/Horas!D66) | E6: =IF(Horas!E66=0,"",Horas!L66/Horas!E66) | F6: =IF(Horas!F66=0,"",Horas!M66/Horas!F66) | G6: =IF(Horas!G66=0,"",Horas!N66/Horas!G66) | H6: =IF(Horas!H66=0,"",Horas!O66/Horas!H66) | I6: =IF(SUM(Horas!C66:H66)=0,"",SUM(Horas!J66:O66)/SUM(Horas!C66:H66)) | L6: Sobreasignado (> umbral)
A7: # Sobreasignados | C7: =COUNTIF(C10:C69,">"&Parametros!$B$8) | D7: =COUNTIF(D10:D69,">"&Parametros!$B$8) | E7: =COUNTIF(E10:E69,">"&Parametros!$B$8) | F7: =COUNTIF(F10:F69,">"&Parametros!$B$8) | G7: =COUNTIF(G10:G69,">"&Parametros!$B$8) | H7: =COUNTIF(H10:H69,">"&Parametros!$B$8) | L7: Asignación sana
A8: # Subutilizados | C8: =COUNTIF(C10:C69,"<"&Parametros!$B$7) | D8: =COUNTIF(D10:D69,"<"&Parametros!$B$7) | E8: =COUNTIF(E10:E69,"<"&Parametros!$B$7) | F8: =COUNTIF(F10:F69,"<"&Parametros!$B$7) | G8: =COUNTIF(G10:G69,"<"&Parametros!$B$7) | H8: =COUNTIF(H10:H69,"<"&Parametros!$B$7) | L8: Subutilizado (< umbral)
A9: Consultor | B9: País | C9: =Asignaciones!J3 | D9: =Asignaciones!K3 | E9: =Asignaciones!L3 | F9: =Asignaciones!M3 | G9: =Asignaciones!N3 | H9: =Asignaciones!O3 | I9: Promedio periodo
A10: =Horas!A6 | B10: =Horas!B6 | C10: =IF($A10="","",IF(N(Horas!C6)=0,"",Horas!J6/Horas!C6)) | D10: =IF($A10="","",IF(N(Horas!D6)=0,"",Horas!K6/Horas!D6)) | E10: =IF($A10="","",IF(N(Horas!E6)=0,"",Horas!L6/Horas!E6)) | F10: =IF($A10="","",IF(N(Horas!F6)=0,"",Horas!M6/Horas!F6)) | G10: =IF($A10="","",IF(N(Horas!G6)=0,"",Horas!N6/Horas!G6)) | H10: =IF($A10="","",IF(N(Horas!H6)=0,"",Horas!O6/Horas!H6)) | I10: =IF($A10="","",IF(SUM(Horas!C6:H6)=0,"",SUM(Horas!J6:O6)/SUM(Horas!C6:H6)))
A11: =Horas!A7 | B11: =Horas!B7 | C11: =IF($A11="","",IF(N(Horas!C7)=0,"",Horas!J7/Horas!C7)) | D11: =IF($A11="","",IF(N(Horas!D7)=0,"",Horas!K7/Horas!D7)) | E11: =IF($A11="","",IF(N(Horas!E7)=0,"",Horas!L7/Horas!E7)) | F11: =IF($A11="","",IF(N(Horas!F7)=0,"",Horas!M7/Horas!F7)) | G11: =IF($A11="","",IF(N(Horas!G7)=0,"",Horas!N7/Horas!G7)) | H11: =IF($A11="","",IF(N(Horas!H7)=0,"",Horas!O7/Horas!H7)) | I11: =IF($A11="","",IF(SUM(Horas!C7:H7)=0,"",SUM(Horas!J7:O7)/SUM(Horas!C7:H7)))
A12: =Horas!A8 | B12: =Horas!B8 | C12: =IF($A12="","",IF(N(Horas!C8)=0,"",Horas!J8/Horas!C8)) | D12: =IF($A12="","",IF(N(Horas!D8)=0,"",Horas!K8/Horas!D8)) | E12: =IF($A12="","",IF(N(Horas!E8)=0,"",Horas!L8/Horas!E8)) | F12: =IF($A12="","",IF(N(Horas!F8)=0,"",Horas!M8/Horas!F8)) | G12: =IF($A12="","",IF(N(Horas!G8)=0,"",Horas!N8/Horas!G8)) | H12: =IF($A12="","",IF(N(Horas!H8)=0,"",Horas!O8/Horas!H8)) | I12: =IF($A12="","",IF(SUM(Horas!C8:H8)=0,"",SUM(Horas!J8:O8)/SUM(Horas!C8:H8)))
A13: =Horas!A9 | B13: =Horas!B9 | C13: =IF($A13="","",IF(N(Horas!C9)=0,"",Horas!J9/Horas!C9)) | D13: =IF($A13="","",IF(N(Horas!D9)=0,"",Horas!K9/Horas!D9)) | E13: =IF($A13="","",IF(N(Horas!E9)=0,"",Horas!L9/Horas!E9)) | F13: =IF($A13="","",IF(N(Horas!F9)=0,"",Horas!M9/Horas!F9)) | G13: =IF($A13="","",IF(N(Horas!G9)=0,"",Horas!N9/Horas!G9)) | H13: =IF($A13="","",IF(N(Horas!H9)=0,"",Horas!O9/Horas!H9)) | I13: =IF($A13="","",IF(SUM(Horas!C9:H9)=0,"",SUM(Horas!J9:O9)/SUM(Horas!C9:H9)))
A14: =Horas!A10 | B14: =Horas!B10 | C14: =IF($A14="","",IF(N(Horas!C10)=0,"",Horas!J10/Horas!C10)) | D14: =IF($A14="","",IF(N(Horas!D10)=0,"",Horas!K10/Horas!D10)) | E14: =IF($A14="","",IF(N(Horas!E10)=0,"",Horas!L10/Horas!E10)) | F14: =IF($A14="","",IF(N(Horas!F10)=0,"",Horas!M10/Horas!F10)) | G14: =IF($A14="","",IF(N(Horas!G10)=0,"",Horas!N10/Horas!G10)) | H14: =IF($A14="","",IF(N(Horas!H10)=0,"",Horas!O10/Horas!H10)) | I14: =IF($A14="","",IF(SUM(Horas!C10:H10)=0,"",SUM(Horas!J10:O10)/SUM(Horas!C10:H10)))
A15: =Horas!A11 | B15: =Horas!B11 | C15: =IF($A15="","",IF(N(Horas!C11)=0,"",Horas!J11/Horas!C11)) | D15: =IF($A15="","",IF(N(Horas!D11)=0,"",Horas!K11/Horas!D11)) | E15: =IF($A15="","",IF(N(Horas!E11)=0,"",Horas!L11/Horas!E11)) | F15: =IF($A15="","",IF(N(Horas!F11)=0,"",Horas!M11/Horas!F11)) | G15: =IF($A15="","",IF(N(Horas!G11)=0,"",Horas!N11/Horas!G11)) | H15: =IF($A15="","",IF(N(Horas!H11)=0,"",Horas!O11/Horas!H11)) | I15: =IF($A15="","",IF(SUM(Horas!C11:H11)=0,"",SUM(Horas!J11:O11)/SUM(Horas!C11:H11)))
A16: =Horas!A12 | B16: =Horas!B12 | C16: =IF($A16="","",IF(N(Horas!C12)=0,"",Horas!J12/Horas!C12)) | D16: =IF($A16="","",IF(N(Horas!D12)=0,"",Horas!K12/Horas!D12)) | E16: =IF($A16="","",IF(N(Horas!E12)=0,"",Horas!L12/Horas!E12)) | F16: =IF($A16="","",IF(N(Horas!F12)=0,"",Horas!M12/Horas!F12)) | G16: =IF($A16="","",IF(N(Horas!G12)=0,"",Horas!N12/Horas!G12)) | H16: =IF($A16="","",IF(N(Horas!H12)=0,"",Horas!O12/Horas!H12)) | I16: =IF($A16="","",IF(SUM(Horas!C12:H12)=0,"",SUM(Horas!J12:O12)/SUM(Horas!C12:H12)))
A17: =Horas!A13 | B17: =Horas!B13 | C17: =IF($A17="","",IF(N(Horas!C13)=0,"",Horas!J13/Horas!C13)) | D17: =IF($A17="","",IF(N(Horas!D13)=0,"",Horas!K13/Horas!D13)) | E17: =IF($A17="","",IF(N(Horas!E13)=0,"",Horas!L13/Horas!E13)) | F17: =IF($A17="","",IF(N(Horas!F13)=0,"",Horas!M13/Horas!F13)) | G17: =IF($A17="","",IF(N(Horas!G13)=0,"",Horas!N13/Horas!G13)) | H17: =IF($A17="","",IF(N(Horas!H13)=0,"",Horas!O13/Horas!H13)) | I17: =IF($A17="","",IF(SUM(Horas!C13:H13)=0,"",SUM(Horas!J13:O13)/SUM(Horas!C13:H13)))
A18: =Horas!A14 | B18: =Horas!B14 | C18: =IF($A18="","",IF(N(Horas!C14)=0,"",Horas!J14/Horas!C14)) | D18: =IF($A18="","",IF(N(Horas!D14)=0,"",Horas!K14/Horas!D14)) | E18: =IF($A18="","",IF(N(Horas!E14)=0,"",Horas!L14/Horas!E14)) | F18: =IF($A18="","",IF(N(Horas!F14)=0,"",Horas!M14/Horas!F14)) | G18: =IF($A18="","",IF(N(Horas!G14)=0,"",Horas!N14/Horas!G14)) | H18: =IF($A18="","",IF(N(Horas!H14)=0,"",Horas!O14/Horas!H14)) | I18: =IF($A18="","",IF(SUM(Horas!C14:H14)=0,"",SUM(Horas!J14:O14)/SUM(Horas!C14:H14)))
A19: =Horas!A15 | B19: =Horas!B15 | C19: =IF($A19="","",IF(N(Horas!C15)=0,"",Horas!J15/Horas!C15)) | D19: =IF($A19="","",IF(N(Horas!D15)=0,"",Horas!K15/Horas!D15)) | E19: =IF($A19="","",IF(N(Horas!E15)=0,"",Horas!L15/Horas!E15)) | F19: =IF($A19="","",IF(N(Horas!F15)=0,"",Horas!M15/Horas!F15)) | G19: =IF($A19="","",IF(N(Horas!G15)=0,"",Horas!N15/Horas!G15)) | H19: =IF($A19="","",IF(N(Horas!H15)=0,"",Horas!O15/Horas!H15)) | I19: =IF($A19="","",IF(SUM(Horas!C15:H15)=0,"",SUM(Horas!J15:O15)/SUM(Horas!C15:H15)))
A20: =Horas!A16 | B20: =Horas!B16 | C20: =IF($A20="","",IF(N(Horas!C16)=0,"",Horas!J16/Horas!C16)) | D20: =IF($A20="","",IF(N(Horas!D16)=0,"",Horas!K16/Horas!D16)) | E20: =IF($A20="","",IF(N(Horas!E16)=0,"",Horas!L16/Horas!E16)) | F20: =IF($A20="","",IF(N(Horas!F16)=0,"",Horas!M16/Horas!F16)) | G20: =IF($A20="","",IF(N(Horas!G16)=0,"",Horas!N16/Horas!G16)) | H20: =IF($A20="","",IF(N(Horas!H16)=0,"",Horas!O16/Horas!H16)) | I20: =IF($A20="","",IF(SUM(Horas!C16:H16)=0,"",SUM(Horas!J16:O16)/SUM(Horas!C16:H16)))
A21: =Horas!A17 | B21: =Horas!B17 | C21: =IF($A21="","",IF(N(Horas!C17)=0,"",Horas!J17/Horas!C17)) | D21: =IF($A21="","",IF(N(Horas!D17)=0,"",Horas!K17/Horas!D17)) | E21: =IF($A21="","",IF(N(Horas!E17)=0,"",Horas!L17/Horas!E17)) | F21: =IF($A21="","",IF(N(Horas!F17)=0,"",Horas!M17/Horas!F17)) | G21: =IF($A21="","",IF(N(Horas!G17)=0,"",Horas!N17/Horas!G17)) | H21: =IF($A21="","",IF(N(Horas!H17)=0,"",Horas!O17/Horas!H17)) | I21: =IF($A21="","",IF(SUM(Horas!C17:H17)=0,"",SUM(Horas!J17:O17)/SUM(Horas!C17:H17)))
... A69: =Horas!A65 | B69: =Horas!B65 | C69: =IF($A69="","",IF(N(Horas!C65)=0,"",Horas!J65/Horas!C65)) | D69: =IF($A69="","",IF(N(Horas!D65)=0,"",Horas!K65/Horas!D65)) | E69: =IF($A69="","",IF(N(Horas!E65)=0,"",Horas!L65/Horas!E65)) | F69: =IF($A69="","",IF(N(Horas!F65)=0,"",Horas!M65/Horas!F65)) | G69: =IF($A69="","",IF(N(Horas!G65)=0,"",Horas!N65/Horas!G65)) | H69: =IF($A69="","",IF(N(Horas!H65)=0,"",Horas!O65/Horas!H65)) | I69: =IF($A69="","",IF(SUM(Horas!C65:H65)=0,"",SUM(Horas!J65:O65)/SUM(Horas!C65:H65)))

Sheet Parametros
A1: Parámetros
A2: Celdas amarillas editables
A3: Parámetro | B3: Valor | C3: Nota
A4: Mes inicial del informe | B4: 46296 | C4: Cualquier fecha del mes; se toma el día 1. El informe muestra 6 meses desde aquí.
A5: Horas estándar por día | B5: 8 | C5: Valor sugerido para nuevos consultores (referencia).
A6: Incluir asignaciones 'Probable' | B6: No | C6: Sí = suma también el pipeline; No = solo Confirmado.
A7: Umbral subutilizado (<) | B7: 0.7 | C7: Por debajo de este % el consultor se marca en ámbar.
A8: Umbral sobreasignado (>) | B8: 1 | C8: Por encima de este % el consultor se marca en rojo.
A10: Cobertura de feriados | B10: =IF(EOMONTH(B4,5)>MIN(MAX(FER_EC),MAX(FER_CO)),"Faltan feriados para el periodo: agrégalos en la hoja Feriados","OK – feriados cargados para todo el periodo")
A12: ¿Quieres ver otros 6 meses? Cambia B4 al nuevo mes inicial (ej. 01-abr-2027) y todo el informe se recorre solo.

Sheet Consultores
A1: Consultores
A2: Un consultor por fila. País: EC o CO (define qué feriados aplican).
A5: Consultor | B5: País | C5: Horas diarias | D5: Rol / Perfil | E5: Notas
A6: Consultor Ejemplo 1 | B6: EC | C6: 8 | D6: Consultor SAS Sr | E6: Ejemplo
A7: Consultor Ejemplo 2 | B7: CO | C7: 8 | D7: Ingeniero de datos Fabric | E7: Ejemplo
A8: Consultor Ejemplo 3 | B8: EC | C8: 4 | D8: Analista gobierno de datos | E8: Ejemplo – medio tiempo

Sheet Feriados
A1: Feriados y días no laborables
A2: Agrega aquí feriados nuevos. Las celdas vacías se ignoran.
A4: ECUADOR | D4: COLOMBIA
A5: Fecha | B5: Descripción | D5: Fecha | E5: Descripción | G5: Fuente: calendarios oficiales publicados (Viceministerio de Turismo EC; Ley 51 de 1983 CO). Cargados hasta dic-2027. Verificar decretos posteriores.
A6: 46304 | B6: Independencia de Guayaquil | D6: 46307 | E6: Día de la Raza
A7: 46328 | B7: Día de Difuntos | D7: 46328 | E7: Todos los Santos
A8: 46329 | B8: Independencia de Cuenca | D8: 46342 | E8: Independencia de Cartagena
A9: 46346 | B9: Suspensión jornada – Decreto Ejecutivo 507 | D9: 46364 | E9: Inmaculada Concepción
A10: 46363 | B10: Fundación de Quito (local Quito, trasladado del 6) | D10: 46381 | E10: Navidad
A11: 46381 | B11: Navidad | D11: 46388 | E11: Año Nuevo
A12: 46388 | B12: Año Nuevo | D12: 46398 | E12: Reyes Magos
A13: 46426 | B13: Carnaval (lunes) | D13: 46468 | E13: San José
A14: 46427 | B14: Carnaval (martes) | D14: 46471 | E14: Jueves Santo
A15: 46472 | B15: Viernes Santo | D15: 46472 | E15: Viernes Santo
A16: 46507 | B16: Día del Trabajo (trasladado del sáb 1-may) | D16: 46508 | E16: Día del Trabajo (sábado)
A17: 46531 | B17: Batalla de Pichincha | D17: 46517 | E17: Ascensión
... A23: 46746 | B23: Navidad (cae sábado, no se traslada) | D23: 46615 | E23: Asunción de la Virgen
D24: 46678 | E24: Día de la Raza
D25: 46692 | E25: Todos los Santos
D26: 46706 | E26: Independencia de Cartagena
D27: 46729 | E27: Inmaculada Concepción
D28: 46746 | E28: Navidad (sábado)

Sheet Asignaciones
A1: Asignaciones consultor – proyecto
A2: Llena A:G. Las columnas H en adelante se calculan (horas y % de cada asignación por mes).
I3: Inicio de mes → | J3: =DATE(YEAR(Parametros!$B$4),MONTH(Parametros!$B$4)+0,1) | K3: =DATE(YEAR(Parametros!$B$4),MONTH(Parametros!$B$4)+1,1) | L3: =DATE(YEAR(Parametros!$B$4),MONTH(Parametros!$B$4)+2,1) | M3: =DATE(YEAR(Parametros!$B$4),MONTH(Parametros!$B$4)+3,1) | N3: =DATE(YEAR(Parametros!$B$4),MONTH(Parametros!$B$4)+4,1) | O3: =DATE(YEAR(Parametros!$B$4),MONTH(Parametros!$B$4)+5,1) | P3: =J3 | Q3: =K3 | R3: =L3 | S3: =M3 | T3: =N3 | U3: =O3
I4: Fin de mes → | J4: =EOMONTH(J3,0) | K4: =EOMONTH(K3,0) | L4: =EOMONTH(L3,0) | M4: =EOMONTH(M3,0) | N4: =EOMONTH(N3,0) | O4: =EOMONTH(O3,0) | P4: =J4 | Q4: =K4 | R4: =L4 | S4: =M4 | T4: =N4 | U4: =O4
A5: Consultor | B5: Proyecto | C5: Cliente | D5: Fecha inicio | E5: Fecha fin | F5: Horas semanales | G5: Estado | H5: País | I5: Horas/día | J5: ="Horas "&TEXT(J3,"mmm-yy") | K5: ="Horas "&TEXT(K3,"mmm-yy") | L5: ="Horas "&TEXT(L3,"mmm-yy") | M5: ="Horas "&TEXT(M3,"mmm-yy") | N5: ="Horas "&TEXT(N3,"mmm-yy") | O5: ="Horas "&TEXT(O3,"mmm-yy") | P5: ="% "&TEXT(J3,"mmm-yy") | Q5: ="% "&TEXT(K3,"mmm-yy") | R5: ="% "&TEXT(L3,"mmm-yy") | S5: ="% "&TEXT(M3,"mmm-yy") | T5: ="% "&TEXT(N3,"mmm-yy") | U5: ="% "&TEXT(O3,"mmm-yy")
A6: Consultor Ejemplo 1 | B6: Migración reglas SAS FD | C6: Cliente A | D6: 46266 | E6: 46444 | F6: 32 | G6: Confirmado | H6: =IF($A6="","",IFERROR(INDEX(Consultores!$B$6:$B$65,MATCH($A6,Consultores!$A$6:$A$65,0)),"No existe")) | I6: =IF($F6="",0,$F6/5) | J6: =_xlfn.LET(_xlpm.inicio,MAX($D6,J$3),_xlpm.fin,MIN($E6,J$4),_xlpm.feriados,IF($H6="CO",FER_CO,FER_EC),_xlpm.dias,IF(_xlpm.inicio>_xlpm.fin,0,NETWORKDAYS(_xlpm.inicio,_xlpm.fin,_xlpm.feriados)),_xlpm.factor,IF($G6="Probable",IF(Parametros!$B$6="Sí",1,0),1),IF(OR($A6="",$D6="",$E6=""),0,_xlpm.dias*$I6*_xlpm.factor)) | K6: =_xlfn.LET(_xlpm.inicio,MAX($D6,K$3),_xlpm.fin,MIN($E6,K$4),_xlpm.feriados,IF($H6="CO",FER_CO,FER_EC),_xlpm.dias,IF(_xlpm.inicio>_xlpm.fin,0,NETWORKDAYS(_xlpm.inicio,_xlpm.fin,_xlpm.feriados)),_xlpm.factor,IF($G6="Probable",IF(Parametros!$B$6="Sí",1,0),1),IF(OR($A6="",$D6="",$E6=""),0,_xlpm.dias*$I6*_xlpm.factor)) | L6: =_xlfn.LET(_xlpm.inicio,MAX($D6,L$3),_xlpm.fin,MIN($E6,L$4),_xlpm.feriados,IF($H6="CO",FER_CO,FER_EC),_xlpm.dias,IF(_xlpm.inicio>_xlpm.fin,0,NETWORKDAYS(_xlpm.inicio,_xlpm.fin,_xlpm.feriados)),_xlpm.factor,IF($G6="Probable",IF(Parametros!$B$6="Sí",1,0),1),IF(OR($A6="",$D6="",$E6=""),0,_xlpm.dias*$I6*_xlpm.factor)) | M6: =_xlfn.LET(_xlpm.inicio,MAX($D6,M$3),_xlpm.fin,MIN($E6,M$4),_xlpm.feriados,IF($H6="CO",FER_CO,FER_EC),_xlpm.dias,IF(_xlpm.inicio>_xlpm.fin,0,NETWORKDAYS(_xlpm.inicio,_xlpm.fin,_xlpm.feriados)),_xlpm.factor,IF($G6="Probable",IF(Parametros!$B$6="Sí",1,0),1),IF(OR($A6="",$D6="",$E6=""),0,_xlpm.dias*$I6*_xlpm.factor)) | N6: =_xlfn.LET(_xlpm.inicio,MAX($D6,N$3),_xlpm.fin,MIN($E6,N$4),_xlpm.feriados,IF($H6="CO",FER_CO,FER_EC),_xlpm.dias,IF(_xlpm.inicio>_xlpm.fin,0,NETWORKDAYS(_xlpm.inicio,_xlpm.fin,_xlpm.feriados)),_xlpm.factor,IF($G6="Probable",IF(Parametros!$B$6="Sí",1,0),1),IF(OR($A6="",$D6="",$E6=""),0,_xlpm.dias*$I6*_xlpm.factor)) | O6: =_xlfn.LET(_xlpm.inicio,MAX($D6,O$3),_xlpm.fin,MIN($E6,O$4),_xlpm.feriados,IF($H6="CO",FER_CO,FER_EC),_xlpm.dias,IF(_xlpm.inicio>_xlpm.fin,0,NETWORKDAYS(_xlpm.inicio,_xlpm.fin,_xlpm.feriados)),_xlpm.factor,IF($G6="Probable",IF(Parametros!$B$6="Sí",1,0),1),IF(OR($A6="",$D6="",$E6=""),0,_xlpm.dias*$I6*_xlpm.factor)) | P6: =_xlfn.LET(_xlpm.horas,J6,_xlpm.feriados,IF($H6="CO",FER_CO,FER_EC),_xlpm.capacidad,NETWORKDAYS(J$3,J$4,_xlpm.feriados)*INDEX(Consultores!$C$6:$C$65,MATCH($A6,Consultores!$A$6:$A$65,0)),IF(_xlpm.horas=0,"",IFERROR(_xlpm.horas/_xlpm.capacidad,""))) | Q6: =_xlfn.LET(_xlpm.horas,K6,_xlpm.feriados,IF($H6="CO",FER_CO,FER_EC),_xlpm.capacidad,NETWORKDAYS(K$3,K$4,_xlpm.feriados)*INDEX(Consultores!$C$6:$C$65,MATCH($A6,Consultores!$A$6:$A$65,0)),IF(_xlpm.horas=0,"",IFERROR(_xlpm.horas/_xlpm.capacidad,""))) | R6: =_xlfn.LET(_xlpm.horas,L6,_xlpm.feriados,IF($H6="CO",FER_CO,FER_EC),_xlpm.capacidad,NETWORKDAYS(L$3,L$4,_xlpm.feriados)*INDEX(Consultores!$C$6:$C$65,MATCH($A6,Consultores!$A$6:$A$65,0)),IF(_xlpm.horas=0,"",IFERROR(_xlpm.horas/_xlpm.capacidad,""))) | S6: =_xlfn.LET(_xlpm.horas,M6,_xlpm.feriados,IF($H6="CO",FER_CO,FER_EC),_xlpm.capacidad,NETWORKDAYS(M$3,M$4,_xlpm.feriados)*INDEX(Consultores!$C$6:$C$65,MATCH($A6,Consultores!$A$6:$A$65,0)),IF(_xlpm.horas=0,"",IFERROR(_xlpm.horas/_xlpm.capacidad,""))) | T6: =_xlfn.LET(_xlpm.horas,N6,_xlpm.feriados,IF($H6="CO",FER_CO,FER_EC),_xlpm.capacidad,NETWORKDAYS(N$3,N$4,_xlpm.feriados)*INDEX(Consultores!$C$6:$C$65,MATCH($A6,Consultores!$A$6:$A$65,0)),IF(_xlpm.horas=0,"",IFERROR(_xlpm.horas/_xlpm.capacidad,""))) | U6: =_xlfn.LET(_xlpm.horas,O6,_xlpm.feriados,IF($H6="CO",FER_CO,FER_EC),_xlpm.capacidad,NETWORKDAYS(O$3,O$4,_xlpm.feriados)*INDEX(Consultores!$C$6:$C$65,MATCH($A6,Consultores!$A$6:$A$65,0)),IF(_xlpm.horas=0,"",IFERROR(_xlpm.horas/_xlpm.capacidad,"")))
A7: Consultor Ejemplo 1 | B7: Soporte Viya | C7: Cliente B | D7: 46296 | E7: 46374 | F7: 16 | G7: Confirmado | H7: =IF($A7="","",IFERROR(INDEX(Consultores!$B$6:$B$65,MATCH($A7,Consultores!$A$6:$A$65,0)),"No existe")) | I7: =IF($F7="",0,$F7/5) | J7: =_xlfn.LET(_xlpm.inicio,MAX($D7,J$3),_xlpm.fin,MIN($E7,J$4),_xlpm.feriados,IF($H7="CO",FER_CO,FER_EC),_xlpm.dias,IF(_xlpm.inicio>_xlpm.fin,0,NETWORKDAYS(_xlpm.inicio,_xlpm.fin,_xlpm.feriados)),_xlpm.factor,IF($G7="Probable",IF(Parametros!$B$6="Sí",1,0),1),IF(OR($A7="",$D7="",$E7=""),0,_xlpm.dias*$I7*_xlpm.factor)) | K7: =_xlfn.LET(_xlpm.inicio,MAX($D7,K$3),_xlpm.fin,MIN($E7,K$4),_xlpm.feriados,IF($H7="CO",FER_CO,FER_EC),_xlpm.dias,IF(_xlpm.inicio>_xlpm.fin,0,NETWORKDAYS(_xlpm.inicio,_xlpm.fin,_xlpm.feriados)),_xlpm.factor,IF($G7="Probable",IF(Parametros!$B$6="Sí",1,0),1),IF(OR($A7="",$D7="",$E7=""),0,_xlpm.dias*$I7*_xlpm.factor)) | L7: =_xlfn.LET(_xlpm.inicio,MAX($D7,L$3),_xlpm.fin,MIN($E7,L$4),_xlpm.feriados,IF($H7="CO",FER_CO,FER_EC),_xlpm.dias,IF(_xlpm.inicio>_xlpm.fin,0,NETWORKDAYS(_xlpm.inicio,_xlpm.fin,_xlpm.feriados)),_xlpm.factor,IF($G7="Probable",IF(Parametros!$B$6="Sí",1,0),1),IF(OR($A7="",$D7="",$E7=""),0,_xlpm.dias*$I7*_xlpm.factor)) | M7: =_xlfn.LET(_xlpm.inicio,MAX($D7,M$3),_xlpm.fin,MIN($E7,M$4),_xlpm.feriados,IF($H7="CO",FER_CO,FER_EC),_xlpm.dias,IF(_xlpm.inicio>_xlpm.fin,0,NETWORKDAYS(_xlpm.inicio,_xlpm.fin,_xlpm.feriados)),_xlpm.factor,IF($G7="Probable",IF(Parametros!$B$6="Sí",1,0),1),IF(OR($A7="",$D7="",$E7=""),0,_xlpm.dias*$I7*_xlpm.factor)) | N7: =_xlfn.LET(_xlpm.inicio,MAX($D7,N$3),_xlpm.fin,MIN($E7,N$4),_xlpm.feriados,IF($H7="CO",FER_CO,FER_EC),_xlpm.dias,IF(_xlpm.inicio>_xlpm.fin,0,NETWORKDAYS(_xlpm.inicio,_xlpm.fin,_xlpm.feriados)),_xlpm.factor,IF($G7="Probable",IF(Parametros!$B$6="Sí",1,0),1),IF(OR($A7="",$D7="",$E7=""),0,_xlpm.dias*$I7*_xlpm.factor)) | O7: =_xlfn.LET(_xlpm.inicio,MAX($D7,O$3),_xlpm.fin,MIN($E7,O$4),_xlpm.feriados,IF($H7="CO",FER_CO,FER_EC),_xlpm.dias,IF(_xlpm.inicio>_xlpm.fin,0,NETWORKDAYS(_xlpm.inicio,_xlpm.fin,_xlpm.feriados)),_xlpm.factor,IF($G7="Probable",IF(Parametros!$B$6="Sí",1,0),1),IF(OR($A7="",$D7="",$E7=""),0,_xlpm.dias*$I7*_xlpm.factor)) | P7: =_xlfn.LET(_xlpm.horas,J7,_xlpm.feriados,IF($H7="CO",FER_CO,FER_EC),_xlpm.capacidad,NETWORKDAYS(J$3,J$4,_xlpm.feriados)*INDEX(Consultores!$C$6:$C$65,MATCH($A7,Consultores!$A$6:$A$65,0)),IF(_xlpm.horas=0,"",IFERROR(_xlpm.horas/_xlpm.capacidad,""))) | Q7: =_xlfn.LET(_xlpm.horas,K7,_xlpm.feriados,IF($H7="CO",FER_CO,FER_EC),_xlpm.capacidad,NETWORKDAYS(K$3,K$4,_xlpm.feriados)*INDEX(Consultores!$C$6:$C$65,MATCH($A7,Consultores!$A$6:$A$65,0)),IF(_xlpm.horas=0,"",IFERROR(_xlpm.horas/_xlpm.capacidad,""))) | R7: =_xlfn.LET(_xlpm.horas,L7,_xlpm.feriados,IF($H7="CO",FER_CO,FER_EC),_xlpm.capacidad,NETWORKDAYS(L$3,L$4,_xlpm.feriados)*INDEX(Consultores!$C$6:$C$65,MATCH($A7,Consultores!$A$6:$A$65,0)),IF(_xlpm.horas=0,"",IFERROR(_xlpm.horas/_xlpm.capacidad,""))) | S7: =_xlfn.LET(_xlpm.horas,M7,_xlpm.feriados,IF($H7="CO",FER_CO,FER_EC),_xlpm.capacidad,NETWORKDAYS(M$3,M$4,_xlpm.feriados)*INDEX(Consultores!$C$6:$C$65,MATCH($A7,Consultores!$A$6:$A$65,0)),IF(_xlpm.horas=0,"",IFERROR(_xlpm.horas/_xlpm.capacidad,""))) | T7: =_xlfn.LET(_xlpm.horas,N7,_xlpm.feriados,IF($H7="CO",FER_CO,FER_EC),_xlpm.capacidad,NETWORKDAYS(N$3,N$4,_xlpm.feriados)*INDEX(Consultores!$C$6:$C$65,MATCH($A7,Consultores!$A$6:$A$65,0)),IF(_xlpm.horas=0,"",IFERROR(_xlpm.horas/_xlpm.capacidad,""))) | U7: =_xlfn.LET(_xlpm.horas,O7,_xlpm.feriados,IF($H7="CO",FER_CO,FER_EC),_xlpm.capacidad,NETWORKDAYS(O$3,O$4,_xlpm.feriados)*INDEX(Consultores!$C$6:$C$65,MATCH($A7,Consultores!$A$6:$A$65,0)),IF(_xlpm.horas=0,"",IFERROR(_xlpm.horas/_xlpm.capacidad,"")))
A8: Consultor Ejemplo 2 | B8: Migración a Fabric | C8: Cliente C | D8: 46310 | E8: 46477 | F8: 40 | G8: Confirmado | H8: =IF($A8="","",IFERROR(INDEX(Consultores!$B$6:$B$65,MATCH($A8,Consultores!$A$6:$A$65,0)),"No existe")) | I8: =IF($F8="",0,$F8/5) | J8: =_xlfn.LET(_xlpm.inicio,MAX($D8,J$3),_xlpm.fin,MIN($E8,J$4),_xlpm.feriados,IF($H8="CO",FER_CO,FER_EC),_xlpm.dias,IF(_xlpm.inicio>_xlpm.fin,0,NETWORKDAYS(_xlpm.inicio,_xlpm.fin,_xlpm.feriados)),_xlpm.factor,IF($G8="Probable",IF(Parametros!$B$6="Sí",1,0),1),IF(OR($A8="",$D8="",$E8=""),0,_xlpm.dias*$I8*_xlpm.factor)) | K8: =_xlfn.LET(_xlpm.inicio,MAX($D8,K$3),_xlpm.fin,MIN($E8,K$4),_xlpm.feriados,IF($H8="CO",FER_CO,FER_EC),_xlpm.dias,IF(_xlpm.inicio>_xlpm.fin,0,NETWORKDAYS(_xlpm.inicio,_xlpm.fin,_xlpm.feriados)),_xlpm.factor,IF($G8="Probable",IF(Parametros!$B$6="Sí",1,0),1),IF(OR($A8="",$D8="",$E8=""),0,_xlpm.dias*$I8*_xlpm.factor)) | L8: =_xlfn.LET(_xlpm.inicio,MAX($D8,L$3),_xlpm.fin,MIN($E8,L$4),_xlpm.feriados,IF($H8="CO",FER_CO,FER_EC),_xlpm.dias,IF(_xlpm.inicio>_xlpm.fin,0,NETWORKDAYS(_xlpm.inicio,_xlpm.fin,_xlpm.feriados)),_xlpm.factor,IF($G8="Probable",IF(Parametros!$B$6="Sí",1,0),1),IF(OR($A8="",$D8="",$E8=""),0,_xlpm.dias*$I8*_xlpm.factor)) | M8: =_xlfn.LET(_xlpm.inicio,MAX($D8,M$3),_xlpm.fin,MIN($E8,M$4),_xlpm.feriados,IF($H8="CO",FER_CO,FER_EC),_xlpm.dias,IF(_xlpm.inicio>_xlpm.fin,0,NETWORKDAYS(_xlpm.inicio,_xlpm.fin,_xlpm.feriados)),_xlpm.factor,IF($G8="Probable",IF(Parametros!$B$6="Sí",1,0),1),IF(OR($A8="",$D8="",$E8=""),0,_xlpm.dias*$I8*_xlpm.factor)) | N8: =_xlfn.LET(_xlpm.inicio,MAX($D8,N$3),_xlpm.fin,MIN($E8,N$4),_xlpm.feriados,IF($H8="CO",FER_CO,FER_EC),_xlpm.dias,IF(_xlpm.inicio>_xlpm.fin,0,NETWORKDAYS(_xlpm.inicio,_xlpm.fin,_xlpm.feriados)),_xlpm.factor,IF($G8="Probable",IF(Parametros!$B$6="Sí",1,0),1),IF(OR($A8="",$D8="",$E8=""),0,_xlpm.dias*$I8*_xlpm.factor)) | O8: =_xlfn.LET(_xlpm.inicio,MAX($D8,O$3),_xlpm.fin,MIN($E8,O$4),_xlpm.feriados,IF($H8="CO",FER_CO,FER_EC),_xlpm.dias,IF(_xlpm.inicio>_xlpm.fin,0,NETWORKDAYS(_xlpm.inicio,_xlpm.fin,_xlpm.feriados)),_xlpm.factor,IF($G8="Probable",IF(Parametros!$B$6="Sí",1,0),1),IF(OR($A8="",$D8="",$E8=""),0,_xlpm.dias*$I8*_xlpm.factor)) | P8: =_xlfn.LET(_xlpm.horas,J8,_xlpm.feriados,IF($H8="CO",FER_CO,FER_EC),_xlpm.capacidad,NETWORKDAYS(J$3,J$4,_xlpm.feriados)*INDEX(Consultores!$C$6:$C$65,MATCH($A8,Consultores!$A$6:$A$65,0)),IF(_xlpm.horas=0,"",IFERROR(_xlpm.horas/_xlpm.capacidad,""))) | Q8: =_xlfn.LET(_xlpm.horas,K8,_xlpm.feriados,IF($H8="CO",FER_CO,FER_EC),_xlpm.capacidad,NETWORKDAYS(K$3,K$4,_xlpm.feriados)*INDEX(Consultores!$C$6:$C$65,MATCH($A8,Consultores!$A$6:$A$65,0)),IF(_xlpm.horas=0,"",IFERROR(_xlpm.horas/_xlpm.capacidad,""))) | R8: =_xlfn.LET(_xlpm.horas,L8,_xlpm.feriados,IF($H8="CO",FER_CO,FER_EC),_xlpm.capacidad,NETWORKDAYS(L$3,L$4,_xlpm.feriados)*INDEX(Consultores!$C$6:$C$65,MATCH($A8,Consultores!$A$6:$A$65,0)),IF(_xlpm.horas=0,"",IFERROR(_xlpm.horas/_xlpm.capacidad,""))) | S8: =_xlfn.LET(_xlpm.horas,M8,_xlpm.feriados,IF($H8="CO",FER_CO,FER_EC),_xlpm.capacidad,NETWORKDAYS(M$3,M$4,_xlpm.feriados)*INDEX(Consultores!$C$6:$C$65,MATCH($A8,Consultores!$A$6:$A$65,0)),IF(_xlpm.horas=0,"",IFERROR(_xlpm.horas/_xlpm.capacidad,""))) | T8: =_xlfn.LET(_xlpm.horas,N8,_xlpm.feriados,IF($H8="CO",FER_CO,FER_EC),_xlpm.capacidad,NETWORKDAYS(N$3,N$4,_xlpm.feriados)*INDEX(Consultores!$C$6:$C$65,MATCH($A8,Consultores!$A$6:$A$65,0)),IF(_xlpm.horas=0,"",IFERROR(_xlpm.horas/_xlpm.capacidad,""))) | U8: =_xlfn.LET(_xlpm.horas,O8,_xlpm.feriados,IF($H8="CO",FER_CO,FER_EC),_xlpm.capacidad,NETWORKDAYS(O$3,O$4,_xlpm.feriados)*INDEX(Consultores!$C$6:$C$65,MATCH($A8,Consultores!$A$6:$A$65,0)),IF(_xlpm.horas=0,"",IFERROR(_xlpm.horas/_xlpm.capacidad,"")))
A9: Consultor Ejemplo 3 | B9: Gobierno de datos | C9: Cliente D | D9: 46330 | E9: 46416 | F9: 20 | G9: Probable | H9: =IF($A9="","",IFERROR(INDEX(Consultores!$B$6:$B$65,MATCH($A9,Consultores!$A$6:$A$65,0)),"No existe")) | I9: =IF($F9="",0,$F9/5) | J9: =_xlfn.LET(_xlpm.inicio,MAX($D9,J$3),_xlpm.fin,MIN($E9,J$4),_xlpm.feriados,IF($H9="CO",FER_CO,FER_EC),_xlpm.dias,IF(_xlpm.inicio>_xlpm.fin,0,NETWORKDAYS(_xlpm.inicio,_xlpm.fin,_xlpm.feriados)),_xlpm.factor,IF($G9="Probable",IF(Parametros!$B$6="Sí",1,0),1),IF(OR($A9="",$D9="",$E9=""),0,_xlpm.dias*$I9*_xlpm.factor)) | K9: =_xlfn.LET(_xlpm.inicio,MAX($D9,K$3),_xlpm.fin,MIN($E9,K$4),_xlpm.feriados,IF($H9="CO",FER_CO,FER_EC),_xlpm.dias,IF(_xlpm.inicio>_xlpm.fin,0,NETWORKDAYS(_xlpm.inicio,_xlpm.fin,_xlpm.feriados)),_xlpm.factor,IF($G9="Probable",IF(Parametros!$B$6="Sí",1,0),1),IF(OR($A9="",$D9="",$E9=""),0,_xlpm.dias*$I9*_xlpm.factor)) | L9: =_xlfn.LET(_xlpm.inicio,MAX($D9,L$3),_xlpm.fin,MIN($E9,L$4),_xlpm.feriados,IF($H9="CO",FER_CO,FER_EC),_xlpm.dias,IF(_xlpm.inicio>_xlpm.fin,0,NETWORKDAYS(_xlpm.inicio,_xlpm.fin,_xlpm.feriados)),_xlpm.factor,IF($G9="Probable",IF(Parametros!$B$6="Sí",1,0),1),IF(OR($A9="",$D9="",$E9=""),0,_xlpm.dias*$I9*_xlpm.factor)) | M9: =_xlfn.LET(_xlpm.inicio,MAX($D9,M$3),_xlpm.fin,MIN($E9,M$4),_xlpm.feriados,IF($H9="CO",FER_CO,FER_EC),_xlpm.dias,IF(_xlpm.inicio>_xlpm.fin,0,NETWORKDAYS(_xlpm.inicio,_xlpm.fin,_xlpm.feriados)),_xlpm.factor,IF($G9="Probable",IF(Parametros!$B$6="Sí",1,0),1),IF(OR($A9="",$D9="",$E9=""),0,_xlpm.dias*$I9*_xlpm.factor)) | N9: =_xlfn.LET(_xlpm.inicio,MAX($D9,N$3),_xlpm.fin,MIN($E9,N$4),_xlpm.feriados,IF($H9="CO",FER_CO,FER_EC),_xlpm.dias,IF(_xlpm.inicio>_xlpm.fin,0,NETWORKDAYS(_xlpm.inicio,_xlpm.fin,_xlpm.feriados)),_xlpm.factor,IF($G9="Probable",IF(Parametros!$B$6="Sí",1,0),1),IF(OR($A9="",$D9="",$E9=""),0,_xlpm.dias*$I9*_xlpm.factor)) | O9: =_xlfn.LET(_xlpm.inicio,MAX($D9,O$3),_xlpm.fin,MIN($E9,O$4),_xlpm.feriados,IF($H9="CO",FER_CO,FER_EC),_xlpm.dias,IF(_xlpm.inicio>_xlpm.fin,0,NETWORKDAYS(_xlpm.inicio,_xlpm.fin,_xlpm.feriados)),_xlpm.factor,IF($G9="Probable",IF(Parametros!$B$6="Sí",1,0),1),IF(OR($A9="",$D9="",$E9=""),0,_xlpm.dias*$I9*_xlpm.factor)) | P9: =_xlfn.LET(_xlpm.horas,J9,_xlpm.feriados,IF($H9="CO",FER_CO,FER_EC),_xlpm.capacidad,NETWORKDAYS(J$3,J$4,_xlpm.feriados)*INDEX(Consultores!$C$6:$C$65,MATCH($A9,Consultores!$A$6:$A$65,0)),IF(_xlpm.horas=0,"",IFERROR(_xlpm.horas/_xlpm.capacidad,""))) | Q9: =_xlfn.LET(_xlpm.horas,K9,_xlpm.feriados,IF($H9="CO",FER_CO,FER_EC),_xlpm.capacidad,NETWORKDAYS(K$3,K$4,_xlpm.feriados)*INDEX(Consultores!$C$6:$C$65,MATCH($A9,Consultores!$A$6:$A$65,0)),IF(_xlpm.horas=0,"",IFERROR(_xlpm.horas/_xlpm.capacidad,""))) | R9: =_xlfn.LET(_xlpm.horas,L9,_xlpm.feriados,IF($H9="CO",FER_CO,FER_EC),_xlpm.capacidad,NETWORKDAYS(L$3,L$4,_xlpm.feriados)*INDEX(Consultores!$C$6:$C$65,MATCH($A9,Consultores!$A$6:$A$65,0)),IF(_xlpm.horas=0,"",IFERROR(_xlpm.horas/_xlpm.capacidad,""))) | S9: =_xlfn.LET(_xlpm.horas,M9,_xlpm.feriados,IF($H9="CO",FER_CO,FER_EC),_xlpm.capacidad,NETWORKDAYS(M$3,M$4,_xlpm.feriados)*INDEX(Consultores!$C$6:$C$65,MATCH($A9,Consultores!$A$6:$A$65,0)),IF(_xlpm.horas=0,"",IFERROR(_xlpm.horas/_xlpm.capacidad,""))) | T9: =_xlfn.LET(_xlpm.horas,N9,_xlpm.feriados,IF($H9="CO",FER_CO,FER_EC),_xlpm.capacidad,NETWORKDAYS(N$3,N$4,_xlpm.feriados)*INDEX(Consultores!$C$6:$C$65,MATCH($A9,Consultores!$A$6:$A$65,0)),IF(_xlpm.horas=0,"",IFERROR(_xlpm.horas/_xlpm.capacidad,""))) | U9: =_xlfn.LET(_xlpm.horas,O9,_xlpm.feriados,IF($H9="CO",FER_CO,FER_EC),_xlpm.capacidad,NETWORKDAYS(O$3,O$4,_xlpm.feriados)*INDEX(Consultores!$C$6:$C$65,MATCH($A9,Consultores!$A$6:$A$65,0)),IF(_xlpm.horas=0,"",IFERROR(_xlpm.horas/_xlpm.capacidad,"")))
H10: =IF($A10="","",IFERROR(INDEX(Consultores!$B$6:$B$65,MATCH($A10,Consultores!$A$6:$A$65,0)),"No existe")) | I10: =IF($F10="",0,$F10/5) | J10: =_xlfn.LET(_xlpm.inicio,MAX($D10,J$3),_xlpm.fin,MIN($E10,J$4),_xlpm.feriados,IF($H10="CO",FER_CO,FER_EC),_xlpm.dias,IF(_xlpm.inicio>_xlpm.fin,0,NETWORKDAYS(_xlpm.inicio,_xlpm.fin,_xlpm.feriados)),_xlpm.factor,IF($G10="Probable",IF(Parametros!$B$6="Sí",1,0),1),IF(OR($A10="",$D10="",$E10=""),0,_xlpm.dias*$I10*_xlpm.factor)) | K10: =_xlfn.LET(_xlpm.inicio,MAX($D10,K$3),_xlpm.fin,MIN($E10,K$4),_xlpm.feriados,IF($H10="CO",FER_CO,FER_EC),_xlpm.dias,IF(_xlpm.inicio>_xlpm.fin,0,NETWORKDAYS(_xlpm.inicio,_xlpm.fin,_xlpm.feriados)),_xlpm.factor,IF($G10="Probable",IF(Parametros!$B$6="Sí",1,0),1),IF(OR($A10="",$D10="",$E10=""),0,_xlpm.dias*$I10*_xlpm.factor)) | L10: =_xlfn.LET(_xlpm.inicio,MAX($D10,L$3),_xlpm.fin,MIN($E10,L$4),_xlpm.feriados,IF($H10="CO",FER_CO,FER_EC),_xlpm.dias,IF(_xlpm.inicio>_xlpm.fin,0,NETWORKDAYS(_xlpm.inicio,_xlpm.fin,_xlpm.feriados)),_xlpm.factor,IF($G10="Probable",IF(Parametros!$B$6="Sí",1,0),1),IF(OR($A10="",$D10="",$E10=""),0,_xlpm.dias*$I10*_xlpm.factor)) | M10: =_xlfn.LET(_xlpm.inicio,MAX($D10,M$3),_xlpm.fin,MIN($E10,M$4),_xlpm.feriados,IF($H10="CO",FER_CO,FER_EC),_xlpm.dias,IF(_xlpm.inicio>_xlpm.fin,0,NETWORKDAYS(_xlpm.inicio,_xlpm.fin,_xlpm.feriados)),_xlpm.factor,IF($G10="Probable",IF(Parametros!$B$6="Sí",1,0),1),IF(OR($A10="",$D10="",$E10=""),0,_xlpm.dias*$I10*_xlpm.factor)) | N10: =_xlfn.LET(_xlpm.inicio,MAX($D10,N$3),_xlpm.fin,MIN($E10,N$4),_xlpm.feriados,IF($H10="CO",FER_CO,FER_EC),_xlpm.dias,IF(_xlpm.inicio>_xlpm.fin,0,NETWORKDAYS(_xlpm.inicio,_xlpm.fin,_xlpm.feriados)),_xlpm.factor,IF($G10="Probable",IF(Parametros!$B$6="Sí",1,0),1),IF(OR($A10="",$D10="",$E10=""),0,_xlpm.dias*$I10*_xlpm.factor)) | O10: =_xlfn.LET(_xlpm.inicio,MAX($D10,O$3),_xlpm.fin,MIN($E10,O$4),_xlpm.feriados,IF($H10="CO",FER_CO,FER_EC),_xlpm.dias,IF(_xlpm.inicio>_xlpm.fin,0,NETWORKDAYS(_xlpm.inicio,_xlpm.fin,_xlpm.feriados)),_xlpm.factor,IF($G10="Probable",IF(Parametros!$B$6="Sí",1,0),1),IF(OR($A10="",$D10="",$E10=""),0,_xlpm.dias*$I10*_xlpm.factor)) | P10: =_xlfn.LET(_xlpm.horas,J10,_xlpm.feriados,IF($H10="CO",FER_CO,FER_EC),_xlpm.capacidad,NETWORKDAYS(J$3,J$4,_xlpm.feriados)*INDEX(Consultores!$C$6:$C$65,MATCH($A10,Consultores!$A$6:$A$65,0)),IF(_xlpm.horas=0,"",IFERROR(_xlpm.horas/_xlpm.capacidad,""))) | Q10: =_xlfn.LET(_xlpm.horas,K10,_xlpm.feriados,IF($H10="CO",FER_CO,FER_EC),_xlpm.capacidad,NETWORKDAYS(K$3,K$4,_xlpm.feriados)*INDEX(Consultores!$C$6:$C$65,MATCH($A10,Consultores!$A$6:$A$65,0)),IF(_xlpm.horas=0,"",IFERROR(_xlpm.horas/_xlpm.capacidad,""))) | R10: =_xlfn.LET(_xlpm.horas,L10,_xlpm.feriados,IF($H10="CO",FER_CO,FER_EC),_xlpm.capacidad,NETWORKDAYS(L$3,L$4,_xlpm.feriados)*INDEX(Consultores!$C$6:$C$65,MATCH($A10,Consultores!$A$6:$A$65,0)),IF(_xlpm.horas=0,"",IFERROR(_xlpm.horas/_xlpm.capacidad,""))) | S10: =_xlfn.LET(_xlpm.horas,M10,_xlpm.feriados,IF($H10="CO",FER_CO,FER_EC),_xlpm.capacidad,NETWORKDAYS(M$3,M$4,_xlpm.feriados)*INDEX(Consultores!$C$6:$C$65,MATCH($A10,Consultores!$A$6:$A$65,0)),IF(_xlpm.horas=0,"",IFERROR(_xlpm.horas/_xlpm.capacidad,""))) | T10: =_xlfn.LET(_xlpm.horas,N10,_xlpm.feriados,IF($H10="CO",FER_CO,FER_EC),_xlpm.capacidad,NETWORKDAYS(N$3,N$4,_xlpm.feriados)*INDEX(Consultores!$C$6:$C$65,MATCH($A10,Consultores!$A$6:$A$65,0)),IF(_xlpm.horas=0,"",IFERROR(_xlpm.horas/_xlpm.capacidad,""))) | U10: =_xlfn.LET(_xlpm.horas,O10,_xlpm.feriados,IF($H10="CO",FER_CO,FER_EC),_xlpm.capacidad,NETWORKDAYS(O$3,O$4,_xlpm.feriados)*INDEX(Consultores!$C$6:$C$65,MATCH($A10,Consultores!$A$6:$A$65,0)),IF(_xlpm.horas=0,"",IFERROR(_xlpm.horas/_xlpm.capacidad,"")))
H11: =IF($A11="","",IFERROR(INDEX(Consultores!$B$6:$B$65,MATCH($A11,Consultores!$A$6:$A$65,0)),"No existe")) | I11: =IF($F11="",0,$F11/5) | J11: =_xlfn.LET(_xlpm.inicio,MAX($D11,J$3),_xlpm.fin,MIN($E11,J$4),_xlpm.feriados,IF($H11="CO",FER_CO,FER_EC),_xlpm.dias,IF(_xlpm.inicio>_xlpm.fin,0,NETWORKDAYS(_xlpm.inicio,_xlpm.fin,_xlpm.feriados)),_xlpm.factor,IF($G11="Probable",IF(Parametros!$B$6="Sí",1,0),1),IF(OR($A11="",$D11="",$E11=""),0,_xlpm.dias*$I11*_xlpm.factor)) | K11: =_xlfn.LET(_xlpm.inicio,MAX($D11,K$3),_xlpm.fin,MIN($E11,K$4),_xlpm.feriados,IF($H11="CO",FER_CO,FER_EC),_xlpm.dias,IF(_xlpm.inicio>_xlpm.fin,0,NETWORKDAYS(_xlpm.inicio,_xlpm.fin,_xlpm.feriados)),_xlpm.factor,IF($G11="Probable",IF(Parametros!$B$6="Sí",1,0),1),IF(OR($A11="",$D11="",$E11=""),0,_xlpm.dias*$I11*_xlpm.factor)) | L11: =_xlfn.LET(_xlpm.inicio,MAX($D11,L$3),_xlpm.fin,MIN($E11,L$4),_xlpm.feriados,IF($H11="CO",FER_CO,FER_EC),_xlpm.dias,IF(_xlpm.inicio>_xlpm.fin,0,NETWORKDAYS(_xlpm.inicio,_xlpm.fin,_xlpm.feriados)),_xlpm.factor,IF($G11="Probable",IF(Parametros!$B$6="Sí",1,0),1),IF(OR($A11="",$D11="",$E11=""),0,_xlpm.dias*$I11*_xlpm.factor)) | M11: =_xlfn.LET(_xlpm.inicio,MAX($D11,M$3),_xlpm.fin,MIN($E11,M$4),_xlpm.feriados,IF($H11="CO",FER_CO,FER_EC),_xlpm.dias,IF(_xlpm.inicio>_xlpm.fin,0,NETWORKDAYS(_xlpm.inicio,_xlpm.fin,_xlpm.feriados)),_xlpm.factor,IF($G11="Probable",IF(Parametros!$B$6="Sí",1,0),1),IF(OR($A11="",$D11="",$E11=""),0,_xlpm.dias*$I11*_xlpm.factor)) | N11: =_xlfn.LET(_xlpm.inicio,MAX($D11,N$3),_xlpm.fin,MIN($E11,N$4),_xlpm.feriados,IF($H11="CO",FER_CO,FER_EC),_xlpm.dias,IF(_xlpm.inicio>_xlpm.fin,0,NETWORKDAYS(_xlpm.inicio,_xlpm.fin,_xlpm.feriados)),_xlpm.factor,IF($G11="Probable",IF(Parametros!$B$6="Sí",1,0),1),IF(OR($A11="",$D11="",$E11=""),0,_xlpm.dias*$I11*_xlpm.factor)) | O11: =_xlfn.LET(_xlpm.inicio,MAX($D11,O$3),_xlpm.fin,MIN($E11,O$4),_xlpm.feriados,IF($H11="CO",FER_CO,FER_EC),_xlpm.dias,IF(_xlpm.inicio>_xlpm.fin,0,NETWORKDAYS(_xlpm.inicio,_xlpm.fin,_xlpm.feriados)),_xlpm.factor,IF($G11="Probable",IF(Parametros!$B$6="Sí",1,0),1),IF(OR($A11="",$D11="",$E11=""),0,_xlpm.dias*$I11*_xlpm.factor)) | P11: =_xlfn.LET(_xlpm.horas,J11,_xlpm.feriados,IF($H11="CO",FER_CO,FER_EC),_xlpm.capacidad,NETWORKDAYS(J$3,J$4,_xlpm.feriados)*INDEX(Consultores!$C$6:$C$65,MATCH($A11,Consultores!$A$6:$A$65,0)),IF(_xlpm.horas=0,"",IFERROR(_xlpm.horas/_xlpm.capacidad,""))) | Q11: =_xlfn.LET(_xlpm.horas,K11,_xlpm.feriados,IF($H11="CO",FER_CO,FER_EC),_xlpm.capacidad,NETWORKDAYS(K$3,K$4,_xlpm.feriados)*INDEX(Consultores!$C$6:$C$65,MATCH($A11,Consultores!$A$6:$A$65,0)),IF(_xlpm.horas=0,"",IFERROR(_xlpm.horas/_xlpm.capacidad,""))) | R11: =_xlfn.LET(_xlpm.horas,L11,_xlpm.feriados,IF($H11="CO",FER_CO,FER_EC),_xlpm.capacidad,NETWORKDAYS(L$3,L$4,_xlpm.feriados)*INDEX(Consultores!$C$6:$C$65,MATCH($A11,Consultores!$A$6:$A$65,0)),IF(_xlpm.horas=0,"",IFERROR(_xlpm.horas/_xlpm.capacidad,""))) | S11: =_xlfn.LET(_xlpm.horas,M11,_xlpm.feriados,IF($H11="CO",FER_CO,FER_EC),_xlpm.capacidad,NETWORKDAYS(M$3,M$4,_xlpm.feriados)*INDEX(Consultores!$C$6:$C$65,MATCH($A11,Consultores!$A$6:$A$65,0)),IF(_xlpm.horas=0,"",IFERROR(_xlpm.horas/_xlpm.capacidad,""))) | T11: =_xlfn.LET(_xlpm.horas,N11,_xlpm.feriados,IF($H11="CO",FER_CO,FER_EC),_xlpm.capacidad,NETWORKDAYS(N$3,N$4,_xlpm.feriados)*INDEX(Consultores!$C$6:$C$65,MATCH($A11,Consultores!$A$6:$A$65,0)),IF(_xlpm.horas=0,"",IFERROR(_xlpm.horas/_xlpm.capacidad,""))) | U11: =_xlfn.LET(_xlpm.horas,O11,_xlpm.feriados,IF($H11="CO",FER_CO,FER_EC),_xlpm.capacidad,NETWORKDAYS(O$3,O$4,_xlpm.feriados)*INDEX(Consultores!$C$6:$C$65,MATCH($A11,Consultores!$A$6:$A$65,0)),IF(_xlpm.horas=0,"",IFERROR(_xlpm.horas/_xlpm.capacidad,"")))
H12: =IF($A12="","",IFERROR(INDEX(Consultores!$B$6:$B$65,MATCH($A12,Consultores!$A$6:$A$65,0)),"No existe")) | I12: =IF($F12="",0,$F12/5) | J12: =_xlfn.LET(_xlpm.inicio,MAX($D12,J$3),_xlpm.fin,MIN($E12,J$4),_xlpm.feriados,IF($H12="CO",FER_CO,FER_EC),_xlpm.dias,IF(_xlpm.inicio>_xlpm.fin,0,NETWORKDAYS(_xlpm.inicio,_xlpm.fin,_xlpm.feriados)),_xlpm.factor,IF($G12="Probable",IF(Parametros!$B$6="Sí",1,0),1),IF(OR($A12="",$D12="",$E12=""),0,_xlpm.dias*$I12*_xlpm.factor)) | K12: =_xlfn.LET(_xlpm.inicio,MAX($D12,K$3),_xlpm.fin,MIN($E12,K$4),_xlpm.feriados,IF($H12="CO",FER_CO,FER_EC),_xlpm.dias,IF(_xlpm.inicio>_xlpm.fin,0,NETWORKDAYS(_xlpm.inicio,_xlpm.fin,_xlpm.feriados)),_xlpm.factor,IF($G12="Probable",IF(Parametros!$B$6="Sí",1,0),1),IF(OR($A12="",$D12="",$E12=""),0,_xlpm.dias*$I12*_xlpm.factor)) | L12: =_xlfn.LET(_xlpm.inicio,MAX($D12,L$3),_xlpm.fin,MIN($E12,L$4),_xlpm.feriados,IF($H12="CO",FER_CO,FER_EC),_xlpm.dias,IF(_xlpm.inicio>_xlpm.fin,0,NETWORKDAYS(_xlpm.inicio,_xlpm.fin,_xlpm.feriados)),_xlpm.factor,IF($G12="Probable",IF(Parametros!$B$6="Sí",1,0),1),IF(OR($A12="",$D12="",$E12=""),0,_xlpm.dias*$I12*_xlpm.factor)) | M12: =_xlfn.LET(_xlpm.inicio,MAX($D12,M$3),_xlpm.fin,MIN($E12,M$4),_xlpm.feriados,IF($H12="CO",FER_CO,FER_EC),_xlpm.dias,IF(_xlpm.inicio>_xlpm.fin,0,NETWORKDAYS(_xlpm.inicio,_xlpm.fin,_xlpm.feriados)),_xlpm.factor,IF($G12="Probable",IF(Parametros!$B$6="Sí",1,0),1),IF(OR($A12="",$D12="",$E12=""),0,_xlpm.dias*$I12*_xlpm.factor)) | N12: =_xlfn.LET(_xlpm.inicio,MAX($D12,N$3),_xlpm.fin,MIN($E12,N$4),_xlpm.feriados,IF($H12="CO",FER_CO,FER_EC),_xlpm.dias,IF(_xlpm.inicio>_xlpm.fin,0,NETWORKDAYS(_xlpm.inicio,_xlpm.fin,_xlpm.feriados)),_xlpm.factor,IF($G12="Probable",IF(Parametros!$B$6="Sí",1,0),1),IF(OR($A12="",$D12="",$E12=""),0,_xlpm.dias*$I12*_xlpm.factor)) | O12: =_xlfn.LET(_xlpm.inicio,MAX($D12,O$3),_xlpm.fin,MIN($E12,O$4),_xlpm.feriados,IF($H12="CO",FER_CO,FER_EC),_xlpm.dias,IF(_xlpm.inicio>_xlpm.fin,0,NETWORKDAYS(_xlpm.inicio,_xlpm.fin,_xlpm.feriados)),_xlpm.factor,IF($G12="Probable",IF(Parametros!$B$6="Sí",1,0),1),IF(OR($A12="",$D12="",$E12=""),0,_xlpm.dias*$I12*_xlpm.factor)) | P12: =_xlfn.LET(_xlpm.horas,J12,_xlpm.feriados,IF($H12="CO",FER_CO,FER_EC),_xlpm.capacidad,NETWORKDAYS(J$3,J$4,_xlpm.feriados)*INDEX(Consultores!$C$6:$C$65,MATCH($A12,Consultores!$A$6:$A$65,0)),IF(_xlpm.horas=0,"",IFERROR(_xlpm.horas/_xlpm.capacidad,""))) | Q12: =_xlfn.LET(_xlpm.horas,K12,_xlpm.feriados,IF($H12="CO",FER_CO,FER_EC),_xlpm.capacidad,NETWORKDAYS(K$3,K$4,_xlpm.feriados)*INDEX(Consultores!$C$6:$C$65,MATCH($A12,Consultores!$A$6:$A$65,0)),IF(_xlpm.horas=0,"",IFERROR(_xlpm.horas/_xlpm.capacidad,""))) | R12: =_xlfn.LET(_xlpm.horas,L12,_xlpm.feriados,IF($H12="CO",FER_CO,FER_EC),_xlpm.capacidad,NETWORKDAYS(L$3,L$4,_xlpm.feriados)*INDEX(Consultores!$C$6:$C$65,MATCH($A12,Consultores!$A$6:$A$65,0)),IF(_xlpm.horas=0,"",IFERROR(_xlpm.horas/_xlpm.capacidad,""))) | S12: =_xlfn.LET(_xlpm.horas,M12,_xlpm.feriados,IF($H12="CO",FER_CO,FER_EC),_xlpm.capacidad,NETWORKDAYS(M$3,M$4,_xlpm.feriados)*INDEX(Consultores!$C$6:$C$65,MATCH($A12,Consultores!$A$6:$A$65,0)),IF(_xlpm.horas=0,"",IFERROR(_xlpm.horas/_xlpm.capacidad,""))) | T12: =_xlfn.LET(_xlpm.horas,N12,_xlpm.feriados,IF($H12="CO",FER_CO,FER_EC),_xlpm.capacidad,NETWORKDAYS(N$3,N$4,_xlpm.feriados)*INDEX(Consultores!$C$6:$C$65,MATCH($A12,Consultores!$A$6:$A$65,0)),IF(_xlpm.horas=0,"",IFERROR(_xlpm.horas/_xlpm.capacidad,""))) | U12: =_xlfn.LET(_xlpm.horas,O12,_xlpm.feriados,IF($H12="CO",FER_CO,FER_EC),_xlpm.capacidad,NETWORKDAYS(O$3,O$4,_xlpm.feriados)*INDEX(Consultores!$C$6:$C$65,MATCH($A12,Consultores!$A$6:$A$65,0)),IF(_xlpm.horas=0,"",IFERROR(_xlpm.horas/_xlpm.capacidad,"")))
H13: =IF($A13="","",IFERROR(INDEX(Consultores!$B$6:$B$65,MATCH($A13,Consultores!$A$6:$A$65,0)),"No existe")) | I13: =IF($F13="",0,$F13/5) | J13: =_xlfn.LET(_xlpm.inicio,MAX($D13,J$3),_xlpm.fin,MIN($E13,J$4),_xlpm.feriados,IF($H13="CO",FER_CO,FER_EC),_xlpm.dias,IF(_xlpm.inicio>_xlpm.fin,0,NETWORKDAYS(_xlpm.inicio,_xlpm.fin,_xlpm.feriados)),_xlpm.factor,IF($G13="Probable",IF(Parametros!$B$6="Sí",1,0),1),IF(OR($A13="",$D13="",$E13=""),0,_xlpm.dias*$I13*_xlpm.factor)) | K13: =_xlfn.LET(_xlpm.inicio,MAX($D13,K$3),_xlpm.fin,MIN($E13,K$4),_xlpm.feriados,IF($H13="CO",FER_CO,FER_EC),_xlpm.dias,IF(_xlpm.inicio>_xlpm.fin,0,NETWORKDAYS(_xlpm.inicio,_xlpm.fin,_xlpm.feriados)),_xlpm.factor,IF($G13="Probable",IF(Parametros!$B$6="Sí",1,0),1),IF(OR($A13="",$D13="",$E13=""),0,_xlpm.dias*$I13*_xlpm.factor)) | L13: =_xlfn.LET(_xlpm.inicio,MAX($D13,L$3),_xlpm.fin,MIN($E13,L$4),_xlpm.feriados,IF($H13="CO",FER_CO,FER_EC),_xlpm.dias,IF(_xlpm.inicio>_xlpm.fin,0,NETWORKDAYS(_xlpm.inicio,_xlpm.fin,_xlpm.feriados)),_xlpm.factor,IF($G13="Probable",IF(Parametros!$B$6="Sí",1,0),1),IF(OR($A13="",$D13="",$E13=""),0,_xlpm.dias*$I13*_xlpm.factor)) | M13: =_xlfn.LET(_xlpm.inicio,MAX($D13,M$3),_xlpm.fin,MIN($E13,M$4),_xlpm.feriados,IF($H13="CO",FER_CO,FER_EC),_xlpm.dias,IF(_xlpm.inicio>_xlpm.fin,0,NETWORKDAYS(_xlpm.inicio,_xlpm.fin,_xlpm.feriados)),_xlpm.factor,IF($G13="Probable",IF(Parametros!$B$6="Sí",1,0),1),IF(OR($A13="",$D13="",$E13=""),0,_xlpm.dias*$I13*_xlpm.factor)) | N13: =_xlfn.LET(_xlpm.inicio,MAX($D13,N$3),_xlpm.fin,MIN($E13,N$4),_xlpm.feriados,IF($H13="CO",FER_CO,FER_EC),_xlpm.dias,IF(_xlpm.inicio>_xlpm.fin,0,NETWORKDAYS(_xlpm.inicio,_xlpm.fin,_xlpm.feriados)),_xlpm.factor,IF($G13="Probable",IF(Parametros!$B$6="Sí",1,0),1),IF(OR($A13="",$D13="",$E13=""),0,_xlpm.dias*$I13*_xlpm.factor)) | O13: =_xlfn.LET(_xlpm.inicio,MAX($D13,O$3),_xlpm.fin,MIN($E13,O$4),_xlpm.feriados,IF($H13="CO",FER_CO,FER_EC),_xlpm.dias,IF(_xlpm.inicio>_xlpm.fin,0,NETWORKDAYS(_xlpm.inicio,_xlpm.fin,_xlpm.feriados)),_xlpm.factor,IF($G13="Probable",IF(Parametros!$B$6="Sí",1,0),1),IF(OR($A13="",$D13="",$E13=""),0,_xlpm.dias*$I13*_xlpm.factor)) | P13: =_xlfn.LET(_xlpm.horas,J13,_xlpm.feriados,IF($H13="CO",FER_CO,FER_EC),_xlpm.capacidad,NETWORKDAYS(J$3,J$4,_xlpm.feriados)*INDEX(Consultores!$C$6:$C$65,MATCH($A13,Consultores!$A$6:$A$65,0)),IF(_xlpm.horas=0,"",IFERROR(_xlpm.horas/_xlpm.capacidad,""))) | Q13: =_xlfn.LET(_xlpm.horas,K13,_xlpm.feriados,IF($H13="CO",FER_CO,FER_EC),_xlpm.capacidad,NETWORKDAYS(K$3,K$4,_xlpm.feriados)*INDEX(Consultores!$C$6:$C$65,MATCH($A13,Consultores!$A$6:$A$65,0)),IF(_xlpm.horas=0,"",IFERROR(_xlpm.horas/_xlpm.capacidad,""))) | R13: =_xlfn.LET(_xlpm.horas,L13,_xlpm.feriados,IF($H13="CO",FER_CO,FER_EC),_xlpm.capacidad,NETWORKDAYS(L$3,L$4,_xlpm.feriados)*INDEX(Consultores!$C$6:$C$65,MATCH($A13,Consultores!$A$6:$A$65,0)),IF(_xlpm.horas=0,"",IFERROR(_xlpm.horas/_xlpm.capacidad,""))) | S13: =_xlfn.LET(_xlpm.horas,M13,_xlpm.feriados,IF($H13="CO",FER_CO,FER_EC),_xlpm.capacidad,NETWORKDAYS(M$3,M$4,_xlpm.feriados)*INDEX(Consultores!$C$6:$C$65,MATCH($A13,Consultores!$A$6:$A$65,0)),IF(_xlpm.horas=0,"",IFERROR(_xlpm.horas/_xlpm.capacidad,""))) | T13: =_xlfn.LET(_xlpm.horas,N13,_xlpm.feriados,IF($H13="CO",FER_CO,FER_EC),_xlpm.capacidad,NETWORKDAYS(N$3,N$4,_xlpm.feriados)*INDEX(Consultores!$C$6:$C$65,MATCH($A13,Consultores!$A$6:$A$65,0)),IF(_xlpm.horas=0,"",IFERROR(_xlpm.horas/_xlpm.capacidad,""))) | U13: =_xlfn.LET(_xlpm.horas,O13,_xlpm.feriados,IF($H13="CO",FER_CO,FER_EC),_xlpm.capacidad,NETWORKDAYS(O$3,O$4,_xlpm.feriados)*INDEX(Consultores!$C$6:$C$65,MATCH($A13,Consultores!$A$6:$A$65,0)),IF(_xlpm.horas=0,"",IFERROR(_xlpm.horas/_xlpm.capacidad,"")))
H14: =IF($A14="","",IFERROR(INDEX(Consultores!$B$6:$B$65,MATCH($A14,Consultores!$A$6:$A$65,0)),"No existe")) | I14: =IF($F14="",0,$F14/5) | J14: =_xlfn.LET(_xlpm.inicio,MAX($D14,J$3),_xlpm.fin,MIN($E14,J$4),_xlpm.feriados,IF($H14="CO",FER_CO,FER_EC),_xlpm.dias,IF(_xlpm.inicio>_xlpm.fin,0,NETWORKDAYS(_xlpm.inicio,_xlpm.fin,_xlpm.feriados)),_xlpm.factor,IF($G14="Probable",IF(Parametros!$B$6="Sí",1,0),1),IF(OR($A14="",$D14="",$E14=""),0,_xlpm.dias*$I14*_xlpm.factor)) | K14: =_xlfn.LET(_xlpm.inicio,MAX($D14,K$3),_xlpm.fin,MIN($E14,K$4),_xlpm.feriados,IF($H14="CO",FER_CO,FER_EC),_xlpm.dias,IF(_xlpm.inicio>_xlpm.fin,0,NETWORKDAYS(_xlpm.inicio,_xlpm.fin,_xlpm.feriados)),_xlpm.factor,IF($G14="Probable",IF(Parametros!$B$6="Sí",1,0),1),IF(OR($A14="",$D14="",$E14=""),0,_xlpm.dias*$I14*_xlpm.factor)) | L14: =_xlfn.LET(_xlpm.inicio,MAX($D14,L$3),_xlpm.fin,MIN($E14,L$4),_xlpm.feriados,IF($H14="CO",FER_CO,FER_EC),_xlpm.dias,IF(_xlpm.inicio>_xlpm.fin,0,NETWORKDAYS(_xlpm.inicio,_xlpm.fin,_xlpm.feriados)),_xlpm.factor,IF($G14="Probable",IF(Parametros!$B$6="Sí",1,0),1),IF(OR($A14="",$D14="",$E14=""),0,_xlpm.dias*$I14*_xlpm.factor)) | M14: =_xlfn.LET(_xlpm.inicio,MAX($D14,M$3),_xlpm.fin,MIN($E14,M$4),_xlpm.feriados,IF($H14="CO",FER_CO,FER_EC),_xlpm.dias,IF(_xlpm.inicio>_xlpm.fin,0,NETWORKDAYS(_xlpm.inicio,_xlpm.fin,_xlpm.feriados)),_xlpm.factor,IF($G14="Probable",IF(Parametros!$B$6="Sí",1,0),1),IF(OR($A14="",$D14="",$E14=""),0,_xlpm.dias*$I14*_xlpm.factor)) | N14: =_xlfn.LET(_xlpm.inicio,MAX($D14,N$3),_xlpm.fin,MIN($E14,N$4),_xlpm.feriados,IF($H14="CO",FER_CO,FER_EC),_xlpm.dias,IF(_xlpm.inicio>_xlpm.fin,0,NETWORKDAYS(_xlpm.inicio,_xlpm.fin,_xlpm.feriados)),_xlpm.factor,IF($G14="Probable",IF(Parametros!$B$6="Sí",1,0),1),IF(OR($A14="",$D14="",$E14=""),0,_xlpm.dias*$I14*_xlpm.factor)) | O14: =_xlfn.LET(_xlpm.inicio,MAX($D14,O$3),_xlpm.fin,MIN($E14,O$4),_xlpm.feriados,IF($H14="CO",FER_CO,FER_EC),_xlpm.dias,IF(_xlpm.inicio>_xlpm.fin,0,NETWORKDAYS(_xlpm.inicio,_xlpm.fin,_xlpm.feriados)),_xlpm.factor,IF($G14="Probable",IF(Parametros!$B$6="Sí",1,0),1),IF(OR($A14="",$D14="",$E14=""),0,_xlpm.dias*$I14*_xlpm.factor)) | P14: =_xlfn.LET(_xlpm.horas,J14,_xlpm.feriados,IF($H14="CO",FER_CO,FER_EC),_xlpm.capacidad,NETWORKDAYS(J$3,J$4,_xlpm.feriados)*INDEX(Consultores!$C$6:$C$65,MATCH($A14,Consultores!$A$6:$A$65,0)),IF(_xlpm.horas=0,"",IFERROR(_xlpm.horas/_xlpm.capacidad,""))) | Q14: =_xlfn.LET(_xlpm.horas,K14,_xlpm.feriados,IF($H14="CO",FER_CO,FER_EC),_xlpm.capacidad,NETWORKDAYS(K$3,K$4,_xlpm.feriados)*INDEX(Consultores!$C$6:$C$65,MATCH($A14,Consultores!$A$6:$A$65,0)),IF(_xlpm.horas=0,"",IFERROR(_xlpm.horas/_xlpm.capacidad,""))) | R14: =_xlfn.LET(_xlpm.horas,L14,_xlpm.feriados,IF($H14="CO",FER_CO,FER_EC),_xlpm.capacidad,NETWORKDAYS(L$3,L$4,_xlpm.feriados)*INDEX(Consultores!$C$6:$C$65,MATCH($A14,Consultores!$A$6:$A$65,0)),IF(_xlpm.horas=0,"",IFERROR(_xlpm.horas/_xlpm.capacidad,""))) | S14: =_xlfn.LET(_xlpm.horas,M14,_xlpm.feriados,IF($H14="CO",FER_CO,FER_EC),_xlpm.capacidad,NETWORKDAYS(M$3,M$4,_xlpm.feriados)*INDEX(Consultores!$C$6:$C$65,MATCH($A14,Consultores!$A$6:$A$65,0)),IF(_xlpm.horas=0,"",IFERROR(_xlpm.horas/_xlpm.capacidad,""))) | T14: =_xlfn.LET(_xlpm.horas,N14,_xlpm.feriados,IF($H14="CO",FER_CO,FER_EC),_xlpm.capacidad,NETWORKDAYS(N$3,N$4,_xlpm.feriados)*INDEX(Consultores!$C$6:$C$65,MATCH($A14,Consultores!$A$6:$A$65,0)),IF(_xlpm.horas=0,"",IFERROR(_xlpm.horas/_xlpm.capacidad,""))) | U14: =_xlfn.LET(_xlpm.horas,O14,_xlpm.feriados,IF($H14="CO",FER_CO,FER_EC),_xlpm.capacidad,NETWORKDAYS(O$3,O$4,_xlpm.feriados)*INDEX(Consultores!$C$6:$C$65,MATCH($A14,Consultores!$A$6:$A$65,0)),IF(_xlpm.horas=0,"",IFERROR(_xlpm.horas/_xlpm.capacidad,"")))
H15: =IF($A15="","",IFERROR(INDEX(Consultores!$B$6:$B$65,MATCH($A15,Consultores!$A$6:$A$65,0)),"No existe")) | I15: =IF($F15="",0,$F15/5) | J15: =_xlfn.LET(_xlpm.inicio,MAX($D15,J$3),_xlpm.fin,MIN($E15,J$4),_xlpm.feriados,IF($H15="CO",FER_CO,FER_EC),_xlpm.dias,IF(_xlpm.inicio>_xlpm.fin,0,NETWORKDAYS(_xlpm.inicio,_xlpm.fin,_xlpm.feriados)),_xlpm.factor,IF($G15="Probable",IF(Parametros!$B$6="Sí",1,0),1),IF(OR($A15="",$D15="",$E15=""),0,_xlpm.dias*$I15*_xlpm.factor)) | K15: =_xlfn.LET(_xlpm.inicio,MAX($D15,K$3),_xlpm.fin,MIN($E15,K$4),_xlpm.feriados,IF($H15="CO",FER_CO,FER_EC),_xlpm.dias,IF(_xlpm.inicio>_xlpm.fin,0,NETWORKDAYS(_xlpm.inicio,_xlpm.fin,_xlpm.feriados)),_xlpm.factor,IF($G15="Probable",IF(Parametros!$B$6="Sí",1,0),1),IF(OR($A15="",$D15="",$E15=""),0,_xlpm.dias*$I15*_xlpm.factor)) | L15: =_xlfn.LET(_xlpm.inicio,MAX($D15,L$3),_xlpm.fin,MIN($E15,L$4),_xlpm.feriados,IF($H15="CO",FER_CO,FER_EC),_xlpm.dias,IF(_xlpm.inicio>_xlpm.fin,0,NETWORKDAYS(_xlpm.inicio,_xlpm.fin,_xlpm.feriados)),_xlpm.factor,IF($G15="Probable",IF(Parametros!$B$6="Sí",1,0),1),IF(OR($A15="",$D15="",$E15=""),0,_xlpm.dias*$I15*_xlpm.factor)) | M15: =_xlfn.LET(_xlpm.inicio,MAX($D15,M$3),_xlpm.fin,MIN($E15,M$4),_xlpm.feriados,IF($H15="CO",FER_CO,FER_EC),_xlpm.dias,IF(_xlpm.inicio>_xlpm.fin,0,NETWORKDAYS(_xlpm.inicio,_xlpm.fin,_xlpm.feriados)),_xlpm.factor,IF($G15="Probable",IF(Parametros!$B$6="Sí",1,0),1),IF(OR($A15="",$D15="",$E15=""),0,_xlpm.dias*$I15*_xlpm.factor)) | N15: =_xlfn.LET(_xlpm.inicio,MAX($D15,N$3),_xlpm.fin,MIN($E15,N$4),_xlpm.feriados,IF($H15="CO",FER_CO,FER_EC),_xlpm.dias,IF(_xlpm.inicio>_xlpm.fin,0,NETWORKDAYS(_xlpm.inicio,_xlpm.fin,_xlpm.feriados)),_xlpm.factor,IF($G15="Probable",IF(Parametros!$B$6="Sí",1,0),1),IF(OR($A15="",$D15="",$E15=""),0,_xlpm.dias*$I15*_xlpm.factor)) | O15: =_xlfn.LET(_xlpm.inicio,MAX($D15,O$3),_xlpm.fin,MIN($E15,O$4),_xlpm.feriados,IF($H15="CO",FER_CO,FER_EC),_xlpm.dias,IF(_xlpm.inicio>_xlpm.fin,0,NETWORKDAYS(_xlpm.inicio,_xlpm.fin,_xlpm.feriados)),_xlpm.factor,IF($G15="Probable",IF(Parametros!$B$6="Sí",1,0),1),IF(OR($A15="",$D15="",$E15=""),0,_xlpm.dias*$I15*_xlpm.factor)) | P15: =_xlfn.LET(_xlpm.horas,J15,_xlpm.feriados,IF($H15="CO",FER_CO,FER_EC),_xlpm.capacidad,NETWORKDAYS(J$3,J$4,_xlpm.feriados)*INDEX(Consultores!$C$6:$C$65,MATCH($A15,Consultores!$A$6:$A$65,0)),IF(_xlpm.horas=0,"",IFERROR(_xlpm.horas/_xlpm.capacidad,""))) | Q15: =_xlfn.LET(_xlpm.horas,K15,_xlpm.feriados,IF($H15="CO",FER_CO,FER_EC),_xlpm.capacidad,NETWORKDAYS(K$3,K$4,_xlpm.feriados)*INDEX(Consultores!$C$6:$C$65,MATCH($A15,Consultores!$A$6:$A$65,0)),IF(_xlpm.horas=0,"",IFERROR(_xlpm.horas/_xlpm.capacidad,""))) | R15: =_xlfn.LET(_xlpm.horas,L15,_xlpm.feriados,IF($H15="CO",FER_CO,FER_EC),_xlpm.capacidad,NETWORKDAYS(L$3,L$4,_xlpm.feriados)*INDEX(Consultores!$C$6:$C$65,MATCH($A15,Consultores!$A$6:$A$65,0)),IF(_xlpm.horas=0,"",IFERROR(_xlpm.horas/_xlpm.capacidad,""))) | S15: =_xlfn.LET(_xlpm.horas,M15,_xlpm.feriados,IF($H15="CO",FER_CO,FER_EC),_xlpm.capacidad,NETWORKDAYS(M$3,M$4,_xlpm.feriados)*INDEX(Consultores!$C$6:$C$65,MATCH($A15,Consultores!$A$6:$A$65,0)),IF(_xlpm.horas=0,"",IFERROR(_xlpm.horas/_xlpm.capacidad,""))) | T15: =_xlfn.LET(_xlpm.horas,N15,_xlpm.feriados,IF($H15="CO",FER_CO,FER_EC),_xlpm.capacidad,NETWORKDAYS(N$3,N$4,_xlpm.feriados)*INDEX(Consultores!$C$6:$C$65,MATCH($A15,Consultores!$A$6:$A$65,0)),IF(_xlpm.horas=0,"",IFERROR(_xlpm.horas/_xlpm.capacidad,""))) | U15: =_xlfn.LET(_xlpm.horas,O15,_xlpm.feriados,IF($H15="CO",FER_CO,FER_EC),_xlpm.capacidad,NETWORKDAYS(O$3,O$4,_xlpm.feriados)*INDEX(Consultores!$C$6:$C$65,MATCH($A15,Consultores!$A$6:$A$65,0)),IF(_xlpm.horas=0,"",IFERROR(_xlpm.horas/_xlpm.capacidad,"")))
H16: =IF($A16="","",IFERROR(INDEX(Consultores!$B$6:$B$65,MATCH($A16,Consultores!$A$6:$A$65,0)),"No existe")) | I16: =IF($F16="",0,$F16/5) | J16: =_xlfn.LET(_xlpm.inicio,MAX($D16,J$3),_xlpm.fin,MIN($E16,J$4),_xlpm.feriados,IF($H16="CO",FER_CO,FER_EC),_xlpm.dias,IF(_xlpm.inicio>_xlpm.fin,0,NETWORKDAYS(_xlpm.inicio,_xlpm.fin,_xlpm.feriados)),_xlpm.factor,IF($G16="Probable",IF(Parametros!$B$6="Sí",1,0),1),IF(OR($A16="",$D16="",$E16=""),0,_xlpm.dias*$I16*_xlpm.factor)) | K16: =_xlfn.LET(_xlpm.inicio,MAX($D16,K$3),_xlpm.fin,MIN($E16,K$4),_xlpm.feriados,IF($H16="CO",FER_CO,FER_EC),_xlpm.dias,IF(_xlpm.inicio>_xlpm.fin,0,NETWORKDAYS(_xlpm.inicio,_xlpm.fin,_xlpm.feriados)),_xlpm.factor,IF($G16="Probable",IF(Parametros!$B$6="Sí",1,0),1),IF(OR($A16="",$D16="",$E16=""),0,_xlpm.dias*$I16*_xlpm.factor)) | L16: =_xlfn.LET(_xlpm.inicio,MAX($D16,L$3),_xlpm.fin,MIN($E16,L$4),_xlpm.feriados,IF($H16="CO",FER_CO,FER_EC),_xlpm.dias,IF(_xlpm.inicio>_xlpm.fin,0,NETWORKDAYS(_xlpm.inicio,_xlpm.fin,_xlpm.feriados)),_xlpm.factor,IF($G16="Probable",IF(Parametros!$B$6="Sí",1,0),1),IF(OR($A16="",$D16="",$E16=""),0,_xlpm.dias*$I16*_xlpm.factor)) | M16: =_xlfn.LET(_xlpm.inicio,MAX($D16,M$3),_xlpm.fin,MIN($E16,M$4),_xlpm.feriados,IF($H16="CO",FER_CO,FER_EC),_xlpm.dias,IF(_xlpm.inicio>_xlpm.fin,0,NETWORKDAYS(_xlpm.inicio,_xlpm.fin,_xlpm.feriados)),_xlpm.factor,IF($G16="Probable",IF(Parametros!$B$6="Sí",1,0),1),IF(OR($A16="",$D16="",$E16=""),0,_xlpm.dias*$I16*_xlpm.factor)) | N16: =_xlfn.LET(_xlpm.inicio,MAX($D16,N$3),_xlpm.fin,MIN($E16,N$4),_xlpm.feriados,IF($H16="CO",FER_CO,FER_EC),_xlpm.dias,IF(_xlpm.inicio>_xlpm.fin,0,NETWORKDAYS(_xlpm.inicio,_xlpm.fin,_xlpm.feriados)),_xlpm.factor,IF($G16="Probable",IF(Parametros!$B$6="Sí",1,0),1),IF(OR($A16="",$D16="",$E16=""),0,_xlpm.dias*$I16*_xlpm.factor)) | O16: =_xlfn.LET(_xlpm.inicio,MAX($D16,O$3),_xlpm.fin,MIN($E16,O$4),_xlpm.feriados,IF($H16="CO",FER_CO,FER_EC),_xlpm.dias,IF(_xlpm.inicio>_xlpm.fin,0,NETWORKDAYS(_xlpm.inicio,_xlpm.fin,_xlpm.feriados)),_xlpm.factor,IF($G16="Probable",IF(Parametros!$B$6="Sí",1,0),1),IF(OR($A16="",$D16="",$E16=""),0,_xlpm.dias*$I16*_xlpm.factor)) | P16: =_xlfn.LET(_xlpm.horas,J16,_xlpm.feriados,IF($H16="CO",FER_CO,FER_EC),_xlpm.capacidad,NETWORKDAYS(J$3,J$4,_xlpm.feriados)*INDEX(Consultores!$C$6:$C$65,MATCH($A16,Consultores!$A$6:$A$65,0)),IF(_xlpm.horas=0,"",IFERROR(_xlpm.horas/_xlpm.capacidad,""))) | Q16: =_xlfn.LET(_xlpm.horas,K16,_xlpm.feriados,IF($H16="CO",FER_CO,FER_EC),_xlpm.capacidad,NETWORKDAYS(K$3,K$4,_xlpm.feriados)*INDEX(Consultores!$C$6:$C$65,MATCH($A16,Consultores!$A$6:$A$65,0)),IF(_xlpm.horas=0,"",IFERROR(_xlpm.horas/_xlpm.capacidad,""))) | R16: =_xlfn.LET(_xlpm.horas,L16,_xlpm.feriados,IF($H16="CO",FER_CO,FER_EC),_xlpm.capacidad,NETWORKDAYS(L$3,L$4,_xlpm.feriados)*INDEX(Consultores!$C$6:$C$65,MATCH($A16,Consultores!$A$6:$A$65,0)),IF(_xlpm.horas=0,"",IFERROR(_xlpm.horas/_xlpm.capacidad,""))) | S16: =_xlfn.LET(_xlpm.horas,M16,_xlpm.feriados,IF($H16="CO",FER_CO,FER_EC),_xlpm.capacidad,NETWORKDAYS(M$3,M$4,_xlpm.feriados)*INDEX(Consultores!$C$6:$C$65,MATCH($A16,Consultores!$A$6:$A$65,0)),IF(_xlpm.horas=0,"",IFERROR(_xlpm.horas/_xlpm.capacidad,""))) | T16: =_xlfn.LET(_xlpm.horas,N16,_xlpm.feriados,IF($H16="CO",FER_CO,FER_EC),_xlpm.capacidad,NETWORKDAYS(N$3,N$4,_xlpm.feriados)*INDEX(Consultores!$C$6:$C$65,MATCH($A16,Consultores!$A$6:$A$65,0)),IF(_xlpm.horas=0,"",IFERROR(_xlpm.horas/_xlpm.capacidad,""))) | U16: =_xlfn.LET(_xlpm.horas,O16,_xlpm.feriados,IF($H16="CO",FER_CO,FER_EC),_xlpm.capacidad,NETWORKDAYS(O$3,O$4,_xlpm.feriados)*INDEX(Consultores!$C$6:$C$65,MATCH($A16,Consultores!$A$6:$A$65,0)),IF(_xlpm.horas=0,"",IFERROR(_xlpm.horas/_xlpm.capacidad,"")))
H17: =IF($A17="","",IFERROR(INDEX(Consultores!$B$6:$B$65,MATCH($A17,Consultores!$A$6:$A$65,0)),"No existe")) | I17: =IF($F17="",0,$F17/5) | J17: =_xlfn.LET(_xlpm.inicio,MAX($D17,J$3),_xlpm.fin,MIN($E17,J$4),_xlpm.feriados,IF($H17="CO",FER_CO,FER_EC),_xlpm.dias,IF(_xlpm.inicio>_xlpm.fin,0,NETWORKDAYS(_xlpm.inicio,_xlpm.fin,_xlpm.feriados)),_xlpm.factor,IF($G17="Probable",IF(Parametros!$B$6="Sí",1,0),1),IF(OR($A17="",$D17="",$E17=""),0,_xlpm.dias*$I17*_xlpm.factor)) | K17: =_xlfn.LET(_xlpm.inicio,MAX($D17,K$3),_xlpm.fin,MIN($E17,K$4),_xlpm.feriados,IF($H17="CO",FER_CO,FER_EC),_xlpm.dias,IF(_xlpm.inicio>_xlpm.fin,0,NETWORKDAYS(_xlpm.inicio,_xlpm.fin,_xlpm.feriados)),_xlpm.factor,IF($G17="Probable",IF(Parametros!$B$6="Sí",1,0),1),IF(OR($A17="",$D17="",$E17=""),0,_xlpm.dias*$I17*_xlpm.factor)) | L17: =_xlfn.LET(_xlpm.inicio,MAX($D17,L$3),_xlpm.fin,MIN($E17,L$4),_xlpm.feriados,IF($H17="CO",FER_CO,FER_EC),_xlpm.dias,IF(_xlpm.inicio>_xlpm.fin,0,NETWORKDAYS(_xlpm.inicio,_xlpm.fin,_xlpm.feriados)),_xlpm.factor,IF($G17="Probable",IF(Parametros!$B$6="Sí",1,0),1),IF(OR($A17="",$D17="",$E17=""),0,_xlpm.dias*$I17*_xlpm.factor)) | M17: =_xlfn.LET(_xlpm.inicio,MAX($D17,M$3),_xlpm.fin,MIN($E17,M$4),_xlpm.feriados,IF($H17="CO",FER_CO,FER_EC),_xlpm.dias,IF(_xlpm.inicio>_xlpm.fin,0,NETWORKDAYS(_xlpm.inicio,_xlpm.fin,_xlpm.feriados)),_xlpm.factor,IF($G17="Probable",IF(Parametros!$B$6="Sí",1,0),1),IF(OR($A17="",$D17="",$E17=""),0,_xlpm.dias*$I17*_xlpm.factor)) | N17: =_xlfn.LET(_xlpm.inicio,MAX($D17,N$3),_xlpm.fin,MIN($E17,N$4),_xlpm.feriados,IF($H17="CO",FER_CO,FER_EC),_xlpm.dias,IF(_xlpm.inicio>_xlpm.fin,0,NETWORKDAYS(_xlpm.inicio,_xlpm.fin,_xlpm.feriados)),_xlpm.factor,IF($G17="Probable",IF(Parametros!$B$6="Sí",1,0),1),IF(OR($A17="",$D17="",$E17=""),0,_xlpm.dias*$I17*_xlpm.factor)) | O17: =_xlfn.LET(_xlpm.inicio,MAX($D17,O$3),_xlpm.fin,MIN($E17,O$4),_xlpm.feriados,IF($H17="CO",FER_CO,FER_EC),_xlpm.dias,IF(_xlpm.inicio>_xlpm.fin,0,NETWORKDAYS(_xlpm.inicio,_xlpm.fin,_xlpm.feriados)),_xlpm.factor,IF($G17="Probable",IF(Parametros!$B$6="Sí",1,0),1),IF(OR($A17="",$D17="",$E17=""),0,_xlpm.dias*$I17*_xlpm.factor)) | P17: =_xlfn.LET(_xlpm.horas,J17,_xlpm.feriados,IF($H17="CO",FER_CO,FER_EC),_xlpm.capacidad,NETWORKDAYS(J$3,J$4,_xlpm.feriados)*INDEX(Consultores!$C$6:$C$65,MATCH($A17,Consultores!$A$6:$A$65,0)),IF(_xlpm.horas=0,"",IFERROR(_xlpm.horas/_xlpm.capacidad,""))) | Q17: =_xlfn.LET(_xlpm.horas,K17,_xlpm.feriados,IF($H17="CO",FER_CO,FER_EC),_xlpm.capacidad,NETWORKDAYS(K$3,K$4,_xlpm.feriados)*INDEX(Consultores!$C$6:$C$65,MATCH($A17,Consultores!$A$6:$A$65,0)),IF(_xlpm.horas=0,"",IFERROR(_xlpm.horas/_xlpm.capacidad,""))) | R17: =_xlfn.LET(_xlpm.horas,L17,_xlpm.feriados,IF($H17="CO",FER_CO,FER_EC),_xlpm.capacidad,NETWORKDAYS(L$3,L$4,_xlpm.feriados)*INDEX(Consultores!$C$6:$C$65,MATCH($A17,Consultores!$A$6:$A$65,0)),IF(_xlpm.horas=0,"",IFERROR(_xlpm.horas/_xlpm.capacidad,""))) | S17: =_xlfn.LET(_xlpm.horas,M17,_xlpm.feriados,IF($H17="CO",FER_CO,FER_EC),_xlpm.capacidad,NETWORKDAYS(M$3,M$4,_xlpm.feriados)*INDEX(Consultores!$C$6:$C$65,MATCH($A17,Consultores!$A$6:$A$65,0)),IF(_xlpm.horas=0,"",IFERROR(_xlpm.horas/_xlpm.capacidad,""))) | T17: =_xlfn.LET(_xlpm.horas,N17,_xlpm.feriados,IF($H17="CO",FER_CO,FER_EC),_xlpm.capacidad,NETWORKDAYS(N$3,N$4,_xlpm.feriados)*INDEX(Consultores!$C$6:$C$65,MATCH($A17,Consultores!$A$6:$A$65,0)),IF(_xlpm.horas=0,"",IFERROR(_xlpm.horas/_xlpm.capacidad,""))) | U17: =_xlfn.LET(_xlpm.horas,O17,_xlpm.feriados,IF($H17="CO",FER_CO,FER_EC),_xlpm.capacidad,NETWORKDAYS(O$3,O$4,_xlpm.feriados)*INDEX(Consultores!$C$6:$C$65,MATCH($A17,Consultores!$A$6:$A$65,0)),IF(_xlpm.horas=0,"",IFERROR(_xlpm.horas/_xlpm.capacidad,"")))
